Workbook

Sheet Formeyannis
G1: Si pas hawkish
A2: Actif | B2: Classe | C2: (exemple) | D2: Position | E2: Poids | F2: AVANT | G2: FED | H2: (%)4 | I2: Product name
A3: SPY | B3: Actions | C3: SPY ou ETF | D3: ETF | E3: Long | F3: 20 | G3: 35 | H3: Risk-on | I3: SPDR S&P 500 ETF Trust / SPY/ ESD | J3: Maybe buy 1 options SPY with expiration date at Month +1
A4: GLD | B4: Or | C4: ETF | D4: Long | F4: 20 | G4: 25 | H4: réels | I4: SPDR Gold Shares | J4: GLD (SPDR Gold Shares | N4: If fed dovish buy options on GLD
A5: CHF | B5: FX | C5: USD/CHF | D5: (short) | E5: Short fx | F5: 25 | G5: 20 | H5: devise | I5: USDCHF
A6: TLT | B6: Taux | C6: TLT (Us treasuries) | D6: ETF ou tx | E6: Long | F6: 20 | G6: 15 | H6: mistake | I6: iShares 20+ Year Treasury Bond ETF | J6: Scénario | K6: SPY | L6: GOLD | M6: USD/CHF | N6: TLT
A7: Silver | B7: Silver | C7: ETF | E7: LONG | F7: 5 | I7: BlackRock Institutional Trust Company N.A. - iShares Silver Trust | J7: Hawkish | K7: 0.35 | L7: 0.25 | M7: 0.25 | N7: 0.15
I8: SLV | J8: Dovish | K8: 0.4 | L8: 0.15 | M8: 0.15 | N8: 0.3
A9: SPY | B9: Options | C9: Options | D9: PUT | E9: Long | F9: Prendre avant
K10: Placement sur 2mois
J11: Short-term corp bond ETF | M11: iShares Short-Term Corporate Bond ETF
J12: IGSB
J13: 1‑2 %
C15: Short USDJPY?? High lvl actually | I15: =250000 -> 250000
I16: =I15-13000 -> 237000 | J16: Build a python code for EQUITIES for jade and others with long short momentum value on 5 best and 5 worst equities of sp500. Each month we buy hold and sell at the end
C17: BTC ETH market neutral strategy | I17: =I15*20% -> 50000
C18: for 1 on short ETH i put 1,33 on LONG BTC | F18: Market neutral bcause 0,85-0,95 correlation | I18: =I15*20% -> 50000
C19: 3,75% LONG BTC | D19: 1,25 Short ETH
J20: - Strike : OTM à ~5–7% sous le prix spot actuel voir -10% otm
J21: - Taille : couvrir ~10–20% de la valeur SPY (ex. protéger 10–20% du portefeuille) selon budget prime.
C22: - Après la FED : réévalue corrélations ; si dovish, augmente TLT/SPY ; si hawkish, réduis SPY et augmente cash/liquidité.

Sheet Our strategy
A1: Asset classes | B1: Risk | C1: Risk ($) | D1: Risk per trade | E1: Risk per trade ($) | F1: Duration / Maturity (we'll see)
A2: Equities | B2: 0.3 | C2: ='Trading Contest rules'!$B$2*'Our strategy'!B2 -> 300000 | D2: 0.15 | E2: =C2*D2 -> 45000
A3: ETF | B3: 0.3 | C3: ='Trading Contest rules'!$B$2*'Our strategy'!B3 -> 300000 | D3: 0.15 | E3: =C3*D3 -> 45000
A4: Swap | B4: 0.2 | C4: ='Trading Contest rules'!$B$2*'Our strategy'!B4 -> 200000 | D4: 0.15 | E4: =C4*D4 -> 30000
A5: Bonds | B5: 0.2 | C5: ='Trading Contest rules'!$B$2*'Our strategy'!B5 -> 200000 | D5: 0.15 | E5: =C5*D5 -> 30000
A6: Forwards | B6: 0.2 | C6: ='Trading Contest rules'!$B$2*'Our strategy'!B6 -> 200000 | D6: 0.15 | E6: =C6*D6 -> 30000
A7: Futures | B7: 0.2 | C7: ='Trading Contest rules'!$B$2*'Our strategy'!B7 -> 200000 | D7: 0.15 | E7: =C7*D7 -> 30000
A8: Repo | B8: 0.2 | C8: ='Trading Contest rules'!$B$2*'Our strategy'!B8 -> 200000 | D8: 0.15 | E8: =C8*D8 -> 30000
A9: Options / Options Spread | B9: 0.2 | C9: ='Trading Contest rules'!$B$2*'Our strategy'!B9 -> 200000 | D9: 0.15 | E9: =C9*D9 -> 30000
A10: Commodities (Through Other asset) | B10: 0.2 | C10: ='Trading Contest rules'!$B$2*'Our strategy'!B10 -> 200000 | D10: 0.15 | E10: =C10*D10 -> 30000
A11: FX | B11: 0.2 | C11: ='Trading Contest rules'!$B$2*'Our strategy'!B11 -> 200000 | D11: 0.15 | E11: =C11*D11 -> 30000
A12: Crypto | B12: 0.05 | C12: ='Trading Contest rules'!$B$2*'Our strategy'!B12 -> 50000 | D12: 0.15 | E12: =7500 -> 7500
A13: Mutuals Funds | B13: 0.05 | C13: ='Trading Contest rules'!$B$2*'Our strategy'!B13 -> 50000 | D13: 0.15 | E13: =C13*D13 -> 7500
H19: Target ROI
H20: 1300000
H21: =(H20/'Trading Contest rules'!B2)-1 -> 0.3

Sheet Trading Contest rules
A1: Base currency | B1: EUR
A2: Initial cash balance | B2: 1000000
A3: interest earn on cash | B3: 0
A4: Interest charge on borrowed funds | B4: 0.03
A6: Minimum stock price for buying | B6: 1
A7: Minimum stock price for selling | B7: 3
A8: Margin trading allowed | B8: Yes
A9: Shot selling allowed | B9: Yes
A10: Maximum leverage | B10: 100% of initial portfolio value
A11: Position limit on a single security | B11: 25% of portfolio value
A13: Orders filled up to | B13: 200% of daily trading volume
A14: Commission | B14: 0.001

Sheet Mutual Fund
A1: Symbol | B1: Company / Fund
A2: 00ACLMX | B2: American Century Capital Portfolios Inc - American
A3: A | B3: Vanguard Scottsdale Funds - Vanguard ST Corporate
A4: AAA | B4: DWS Alternative Asset Allocation Plus Fund CI A
A5: AAAAX | B5: DWS ALTN Asset Alloc Plus (A)
A6: AAACX | B6: A3 Alternative Credit Fund
A7: AAADX | B7: Alpine Accelerating Dividend Fund
A8: AAAEX | B8: AllianzGI Health Sciences Fund
A9: AAAFX | B9: American Century Asset Allocation Portfolios Inc
A10: AAAGX | B10: Thrivent Large Cap Growth Fund
A11: AAAHX | B11: American Century Asset Allocation Portfolios Inc
A12: BCFGX | B12: Bryce Capital Growth Fund
... A102: ADR | B102: Dreyfus Satellite Alpha Fund

Sheet Trading_Journal
A1: Trade ID | B1: Trader | C1: Trade date | D1: Type | E1: Trading Session | F1: Instrument | G1: Underlying asset | H1: Asset Class | I1: Option direction | J1: Direction | K1: Price paid | L1: Qty | M1: Amount($) | N1: Stop Loss Set | O1: Take Profit Set | P1: Commission + Fees | Q1: Curr./Exch | R1: Amount(€) | S1: Risk (€) | T1: % Portfolio Risked | U1: Position Limit % | V1: Setup Type | W1: Market Context | X1: Catalyst / Trigger | Y1: Hypothesis | Z1: Expected Duration | AA1: Emotional State at Entry | AB1: Emotional State at Exit | AC1: What Worked | AD1: What Didn’t | AE1: What to Improve Next Time | AF1: Major Economic News / Releases | AG1: Inter-Market Observations | AH1: Unexpected Events Affecting Trade | AI1: Strategy | AJ1: Time Frame
A2: 1 | B2: Yannis Khalfi | C2: 46044.8 | D2: Market | E2: Asia | F2: Forex | G2: EUR/USD | H2: FX | J2: Buy
A3: 2 | B3: Yannis Khalfi | C3: 46044.802 | D3: Market | E3: Asia | F3: Forex | G3: EUR/USD | H3: FX | J3: Sell
A4: 3 | B4: Yannis Khalfi | C4: 46048.295 | D4: Market | E4: Asia | F4: Cryptos | G4: BTC | H4: Crypto | J4: Buy | K4: 87701.2 | L4: 0.1709 | M4: -12600.58 | N4: 65000 | O4: 97000(minimum) | P4: =-10 -> -10 | Q4: 0.8407 | R4: =M4*Q4 -> -10593.308 | S4: =ABS(R4) -> 10593.308 | T4: =S4/1000000 -> 0.010593308 | U4: 10-12% | V4: Safe Haven | W4: Tense geopolitical context involving Trump and Greenland. Three days ahead of the Fed rate decision. BTC at a key technical level. I expect investor inflows if conditions deteriorate further. | X4: Risky Safe haven inflows | Y4: BTC come back some strength | Z4: Short term swing | AA4: Confident | AB4: Calm | AF4: FED Rates in 3 days. Wednesday 28/01/2026 | AI4: Macro on Crypto | AJ4: D
A5: 4 | B5: Yannis Khalfi | C5: 46048.648 | D5: Market | E5: NY | F5: ETF | G5: SPY | H5: ETF | J5: Buy | K5: 690.93 | L5: 65 | M5: =-37756.37 -> -37756.37 | N5: 650.4 | P5: =-10 -> -10 | Q5: 0.8407 | R5: =M5*Q5 -> -31741.78 | S5: =ABS(R5) -> 31741.78 | T5: =S5/1000000 -> 0.03174178 | U5: 0.08 | V5: Passive income | W5: High volatility, fed rates announcement soon. Stocks can go high if rates are getting lowered | X5: Good ROI on this benchmark | Y5: USD weakness - More exportation More money for US STOCKS | Z5: Short term swing | AA5: Confident | AF5: FED Rates in 3 days. Wednesday 28/01/2026 | AI5: Macro on Stocks | AJ5: D
A6: 5 | B6: Jade Sancho | C6: 46049.646 | D6: Limit | E6: NY | F6: Option | G6: NVDA | H6: Call | I6: Long | J6: Buy | K6: 3.4 | L6: 100 | M6: =-28624.35 -> -28624.35 | O6: 10% profit | P6: -1 | Q6: 0.84189 | R6: =M6*Q6 -> -24098.554 | S6: =ABS(R6) -> 24098.554 | T6: =S6/1000000 -> 0.024098554 | V6: moderated risk | W6: Given heightened macroeconomic uncertainty around Federal Reserve communication, we implemented a short-term ATM straddle on NVIDIA, a high-beta technology stock, to capture potential volatility expansion. | X6: Risky Safe haven inflows | Y6: If big shift in NASDAQ after fed news, NVDA will shift accordingly | Z6: Short term swing | AA6: Depends on Fed news | AB6: Could have waited longer, but no loss occured | AF6: FED Rates in 3 days. Wednesday 28/01/2026 | AG6: The sharp decline in Nvidia followed earnings despite strong fundamentals, mainly due to extreme pre-earnings expectations, profit-taking, and options-driven hedging flows amplifying the downside move | AI6: Macro on options | AJ6: W
A7: 6 | B7: Jade Sancho | C7: 46049.646 | D7: Limit | E7: NY | F7: Option | G7: NVDA | H7: Put | I7: Long | J7: Buy | K7: 6.7 | L7: 100 | M7: -56406.8 | O7: 10% profit | P7: -1 | Q7: 0.84189 | R7: =M7*Q7 -> -47488.321 | S7: =ABS(R7) -> 47488.321 | T7: =S7/1000000 -> 0.047488321 | V7: moderated risk | W7: Straddle has worked, Nvidia share price moved down a lot and we have a profit on the put vs the call. is is time to close the position | X7: Risky Safe haven inflows | Y7: If big shift in NASDAQ after fed news, NVDA will shift accordingly | Z7: Short term swing | AA7: Depends on Fed news | AB7: Could have waited longer, but no loss occured | AF7: FED Rates in 3 days. Wednesday 28/01/2026 | AI7: Macro on options | AJ7: W
A8: 7 | B8: Wang Jialei | C8: 46050.008 | D8: Market | E8: Asia | F8: Forex | G8: EUR/USD | H8: FX | J8: Buy | K8: 1.20324 | L8: 42000 | M8: =-(L8*K8)*Q8 -> -42545.82 | N8: 1.1448 | O8: 1.26916 | P8: -1 | Q8: 0.84189 | R8: =M8*Q8 -> -35818.901 | S8: 0 | T8: =S8/1000000 -> 0 | U8: 0.06
A9: 8 | B9: Wang Jialei | C9: 46050.009 | D9: Market | E9: Asia | F9: Forex | G9: GBP/USD | H9: FX | J9: Buy | K9: 1.38352 | L9: 34000 | M9: =-(L9*K9)*Q9 -> -39602.236 | N9: 1.30228 | O9: 1.45399 | P9: -1 | Q9: 0.84189 | R9: =M9*Q9 -> -33340.727 | S9: 0 | T9: =S9/1000000 -> 0 | U9: 0.06
A10: 9 | B10: Yannis Khalfi | C10: 46051.646 | D10: Market | E10: NY | F10: Commodity | G10: Silver | H10: Commodity | J10: Buy | K10: 121.479 | L10: 300 | M10: -30472.09 | O10: Looking for a 10% profit | P10: -1 | Q10: 0.83614 | R10: =M10*Q10 -> -25478.933 | S10: =ABS(R10) -> 25478.933 | T10: =S10/1000000 -> 0.025478933 | U10: 30 | V10: Safe haven | W10: Rising gold prices due to geopolitical tensions and Trump announcement. Silver is supposed to follow | X10: Safe haven inflows | Y10: Gold rally continues on macro risk - Silver will follow | Z10: Short term swing | AA10: Confident but a bit stressed because it's overexpended right now | AB10: Mitigated | AF10: FED didn't moved rate yesterday, but TRUMP confirmed that the dollar is in perfect condition and it's lvl of price is perfect. He can do "YOYO" as he said. He wants dollar to be more weak | AG10: USD weakness supported gold | AI10: Global macro | AJ10: D
A11: 10 | B11: Yannis Khalfi | C11: 46052.646 | D11: Market | E11: NY | F11: Commodity | G11: GOLD | H11: Commodity | J11: Buy | K11: 5551.5 | L11: 7 | M11: -32492.87 | O11: Looking for a 10% profit | P11: -1 | Q11: 0.83614 | R11: =M11*Q11 -> -27168.588 | S11: =ABS(R11) -> 27168.588 | T11: =S11/1000000 -> 0.027168588 | U11: 30 | V11: Safe haven | W11: Rising gold prices due to geopolitical tensions and Trump announcement | X11: Safe haven inflows | Y11: Gold rally continues on macro risk | Z11: Short term swing | AA11: Confident but a bit stressed because it's overexpended right now | AB11: Mitigated | AF11: FED didn't moved rate yesterday, but TRUMP confirmed that the dollar is in perfect condition and it's lvl of price is perfect. He can do "YOYO" as he said. He wants dollar to be more weak | AG11: USD weakness supported gold | AI11: Global macro | AJ11: D
A12: 11 | B12: Jade Sancho | C12: 46056.705 | D12: Limit | E12: NY | F12: Option | G12: NVDA | H12: Call | I12: Long | J12: Sell | K12: 0.56 | L12: -100 | M12: 4748.14 | P12: -1 | Q12: 0.84788 | R12: =M12*Q12 -> 4025.8529 | S12: =ABS(R12) -> 4025.8529 | T12: =S12/1000000 -> 0.0040258529
A13: 12 | B13: Jade Sancho | C13: 46056.705 | D13: Limit | E13: NY | F13: Option | G13: NVDA | H13: Put | I13: Long | J13: Sell | K13: 9.71 | L13: -100 | M13: 82329.3 | P13: -1 | Q13: 0.84788 | R13: =M13*Q13 -> 69805.367 | S13: =ABS(R13) -> 69805.367 | T13: =S13/1000000 -> 0.069805367
A14: 13 | B14: Yannis Khalfi | C14: 46058.847 | D14: Market | E14: NY | F14: Cryptos | G14: BTC | H14: Crypto | J14: Sell | K14: 66137.21 | L14: -0.1709 | M14: 9572.93 | P14: -1 | Q14: 0.84695 | R14: =M14*Q14 -> 8107.7931 | S14: =ABS(R14) -> 8107.7931 | T14: =S14/1000000 -> 0.0081077931
A15: 14 | B15: Wanchun Cui | C15: 46059.746 | D15: Market | E15: NY | F15: Fixed Income | G15: T-BOND 3.125% 15/05/2048 | H15: Bond | J15: Buy | K15: 755.21622 | L15: 1 | M15: -647.2 | O15: Looking for a 10% profit | P15: -1 | Q15: 0.84917 | R15: =M15*Q15 -> -549.58282 | S15: =ABS(R15) -> 549.58282 | T15: =S15/1000000 -> 0.00054958282 | U15: 15 | V15: Macro / Duration Trade | W15: Late-cycle, slowing growth, long-end yields elevated | X15: Expected Fed pivot / recession risk / risk-off flows | Y15: Long-end US yields will decline, driving price appreciation via duration and convexity | Z15: middle term | AA15: Calm / Conviction-based | AB15: N/A | AI15: Global macro | AJ15: 5m
A16: 15 | B16: Jade Sancho | C16: 46059.751 | D16: Limit | E16: NY | F16: Option | G16: Microsoft | H16: Call | I16: Long | J16: Buy | K16: 7.75 | L16: 50 | M16: -32905.35 | O16: Looking for 20% profit | P16: -1 | Q16: 0.84917 | R16: =M16*Q16 -> -27942.236 | S16: =ABS(R16) -> 27942.236 | T16: =S16/1000000 -> 0.027942236 | V16: safe Haven | W16: Microsoft just went down 20% due to technological gap, time to invest before it goes up | X16: Safe haven inflows | Y16: Invest in a call as we hope for a increase in Microsoft stock price as there was a sharp decline previously | Z16: Short term swing | AA16: Calm / Conviction-based | AB16: confident | AI16: Macro on options | AJ16: 2D
A17: 16 | B17: Wanchun Cui | C17: 46059.753 | D17: Market | E17: NY | F17: Fixed Income | G17: T-BOND 3.125% 15/05/2048 | H17: Bond | J17: Buy | K17: 755.21622 | L17: 45 | M17: =-29123.83 -> -29123.83 | O17: Looking for a 10% profit | P17: -1 | Q17: 0.84917 | R17: =M17*Q17 -> -24731.083 | S17: =ABS(R17) -> 24731.083 | T17: =S17/1000000 -> 0.024731083 | U17: 15 | V17: Macro / Duration Trade | W17: Late-cycle, slowing growth, long-end yields elevated | X17: Expected Fed pivot / recession risk / risk-off flows | Y17: Long-end US yields will decline, driving price appreciation via duration and convexity | Z17: middle term | AA17: Calm / Conviction-based | AB17: N/A | AI17: Global macro | AJ17: 5m
A18: 17 | B18: Wanchun Cui | C18: 46060.125 | D18: Market | E18: Asia | F18: Fixed Income | G18: BUND 1.250% 15-Nov-2048 | H18: Bond | J18: Buy | K18: 660.46 | L18: 22 | M18: -14660.46 | O18: Looking for a 10% profit | P18: -1 | Q18: 1 | R18: =M18*Q18 -> -14660.46 | S18: =ABS(R18) -> 14660.46 | T18: =S18/1000000 -> 0.01466046 | U18: 15 | V18: Macro / Duration Trade | W18: Late-cycle, slowing growth, long-end yields elevated | X18: Expected Fed pivot / recession risk / risk-off flows | Y18: Long-end US yields will decline, driving price appreciation via duration and convexity | Z18: middle term | AA18: Calm / Conviction-based | AB18: N/A | AI18: Global macro | AJ18: 5m
A19: 18 | B19: Wanchun Cui | C19: 46062.385 | D19: Market | E19: London | F19: Fixed Income | G19: BTP 3.100% 03-Jan-2040 | H19: Bond | J19: Buy | K19: 926.261 | L19: 15 | M19: -14096.48 | O19: According to Bond strategy | P19: -1 | Q19: 1 | R19: =M19*Q19 -> -14096.48 | S19: =ABS(R19) -> 14096.48 | T19: =S19/1000000 -> 0.01409648 | Y19: BTP 2040 LONG to express ECB easing and Italy spread compression. High duration and clean rates/spread beta with manageable volatility over 2-month horizon. | AI19: Bond strategy
A20: 19 | B20: Wanchun Cui | C20: 46062.646 | D20: Market | E20: NY | F20: Fixed Income | G20: Microsoft Corp - 5.2% - Jun 2039 | H20: Bond | J20: Buy | K20: 1044.1575 | L20: 23 | M20: -20522.61 | O20: According to Bond strategy | P20: -1 | Q20: 0.8467 | R20: =M20*Q20 -> -17376.494 | S20: =ABS(R20) -> 17376.494 | T20: =S20/1000000 -> 0.017376494 | Y20: Long MSFT 2039 for rate-cut convexity and carry. Premium justified by high coupon vs market yield; benefit from long-end yield compression. | AI20: Bond strategy
A21: 20 | B21: Wanchun Cui | C21: 46062.646 | D21: Market | E21: NY | F21: Fixed Income | G21: Apple Inc - 1.700% - Aug 2031 | H21: Bond | J21: Buy | K21: 888.02 | L21: 27 | M21: -20303 | O21: According to Bond strategy | P21: -1 | Q21: 0.8467 | R21: =M21*Q21 -> -17190.55 | S21: =ABS(R21) -> 17190.55 | T21: =S21/1000000 -> 0.01719055 | Y21: Buy Apple 2031 as a low-coupon IG bond with high duration. Positioned to benefit from potential rate cuts; strong balance sheet limits credit risk. | AI21: Bond strategy
A22: 21 | B22: Wanchun Cui | C22: 46062.646 | D22: Market | E22: NY | F22: Fixed Income | G22: Ford Motor Co. - 7.500% - Aug 2026 | H22: Bond | J22: Buy | K22: 1012.2 | L22: 20 | M22: -17161.41 | O22: According to Bond strategy | P22: -1 | Q22: 0.8467 | R22: =M22*Q22 -> -14530.566 | S22: =ABS(R22) -> 14530.566 | T22: =S22/1000000 -> 0.014530566 | Y22: Long Ford 7.5% Aug-2026 for short-dated high-carry credit exposure. Trade focuses on yield capture and pull-to-par with limited duration risk, supported by near-term maturity and manageable refinancing profile. | AI22: Bond strategy
A23: 22 | B23: Wanchun Cui | C23: 46062.646 | D23: Market | E23: NY | F23: Fixed Income | G23: Kraft Heinz Foods - 6.500% - Feb 2040 | H23: Bond | J23: Buy | K23: 1084.61 | L23: 19 | M23: -17445.52 | O23: According to Bond strategy | P23: -1 | Q23: 0.8467 | R23: =M23*Q23 -> -14771.122 | S23: =ABS(R23) -> 14771.122 | T23: =S23/1000000 -> 0.014771122 | Y23: Long Kraft Heinz 6.5% Feb-2040 to capture high coupon carry and defensive consumer-staples credit exposure. Position targets income-driven returns with moderate duration sensitivity, supported by resilient cash flows and non-cyclical demand. | AI23: Bond strategy
A24: 23 | B24: Wanchun Cui | C24: 46062.646 | D24: Market | E24: NY | F24: Fixed Income | G24: Altria Group Inc - 9.95% - Nov 2038 | H24: Bond | J24: Buy | K24: 1366.1 | L24: 12 | M24: -14126.58 | O24: According to Bond strategy | P24: -1 | Q24: 0.8467 | R24: =M24*Q24 -> -11960.975 | S24: =ABS(R24) -> 11960.975 | T24: =S24/1000000 -> 0.011960975 | Y24: High-carry defensive credit. Locking ~10% coupon from stable cash-flow issuer to anchor portfolio yield and offset rate/tech volatility. | AI24: Bond strategy
A25: 24 | B25: Wanchun Cui | C25: 46062.646 | D25: Market | E25: NY | F25: Fixed Income | G25: Philip Morris - 6.375% - May 2038 | H25: Bond | J25: Buy | K25: 1114.28 | L25: 15 | M25: -14335.98 | O25: According to Bond strategy | P25: -1 | Q25: 0.8467 | R25: =M25*Q25 -> -12138.274 | S25: =ABS(R25) -> 12138.274 | T25: =S25/1000000 -> 0.012138274 | Y25: High-carry defensive credit. Stable global tobacco cash flows support attractive income and portfolio yield stabilization. | AI25: Bond strategy
A26: 25 | B26: Wanchun Cui | C26: 46062.646 | D26: Market | E26: NY | F26: Fixed Income | G26: Boeing | H26: Bond | J26: Buy | K26: 1090 | L26: 15 | M26: -14118.6 | O26: According to Bond strategy | P26: -1 | Q26: 0.8467 | R26: =M26*Q26 -> -11954.219 | S26: =ABS(R26) -> 11954.219 | T26: =S26/1000000 -> 0.011954219 | Y26: Cyclical recovery credit with elevated carry. Position targets spread compression as Boeing normalizes operations and cash flow over the cycle. | AI26: Bond strategy
A27: 26 | B27: Wanchun Cui | C27: 46062.646 | D27: Market | E27: NY | F27: Fixed Income | G27: United States Steel Corp - 6.875% - Mar 2029 | H27: Bond | J27: Buy | K27: 1004.57 | L27: 10 | M27: -8759.24 | O27: According to Bond strategy | P27: -1 | Q27: 0.8467 | R27: =M27*Q27 -> -7416.4485 | S27: =ABS(R27) -> 7416.4485 | T27: =S27/1000000 -> 0.0074164485 | Y27: Short-dated cyclical credit capturing high carry with limited duration risk. Trade targets stable income and near-term spread normalization into 2029 maturity. | AI27: Bond strategy
A28: 27 | B28: Wanchun Cui | C28: 46062.646 | D28: Market | E28: NY | F28: Fixed Income | G28: JPMORGAN CHASE & CO - 6.4% - May 2038 | H28: Bond | J28: Buy | K28: 1125.29 | L28: 10 | M28: -9652.51 | O28: According to Bond strategy | P28: -1 | Q28: 0.8467 | R28: =M28*Q28 -> -8172.7802 | S28: =ABS(R28) -> 8172.7802 | T28: =S28/1000000 -> 0.0081727802 | Y28: Long JPM 6.4% May-2038 as a credit relative value anchor. High coupon provides strong carry while long maturity offers duration exposure. Position expresses bank credit stability with limited idiosyncratic risk and benefits from spread compression or long-end yield declines. | AI28: Bond strategy
A29: 28 | B29: Wanchun Cui | C29: 46062.646 | D29: Market | E29: NY | F29: Fixed Income | G29: JPMORGAN CHASE & CO - 5.5% - Oct 2040 | H29: Bond | J29: Buy | K29: 1045.52 | L29: 8 | M29: -7199.29 | O29: According to Bond strategy | P29: -1 | Q29: 0.8467 | R29: =M29*Q29 -> -6095.6388 | S29: =ABS(R29) -> 6095.6388 | T29: =S29/1000000 -> 0.0060956388 | Y29: Long JPM 5.5% Oct-2040 to extend bank credit duration with stable carry. Position targets long-end rate sensitivity and potential credit spread tightening while maintaining exposure to a high-quality global systemically important bank. | AI29: Bond strategy
A30: 29 | B30: Jade Sancho | C30: 46062.908 | D30: Limit | E30: NY | F30: Option | G30: Microsoft | H30: Call | I30: Long | J30: Sell | K30: 18.85 | L30: -50 | M30: 79801.2 | O30: Let's see where volatility brings us | P30: -1 | Q30: 0.8467 | R30: =M30*Q30 -> 67567.676 | S30: =ABS(R30) -> 67567.676 | T30: =S30/1000000 -> 0.067567676 | Y30: The price of Microsoft went up again like predicted, it is time to close the call as we have made the expected profit to not take any further risk. | AI30: Bond strategy
A31: 30 | B31: Wanchun Cui | C31: 46062.917 | D31: Market | E31: NY | F31: Fixed Income | G31: OAT 3.250% 25-May-2045 | H31: Bond | J31: Buy | K31: 888.3 | L31: 16 | M31: -14318.22 | O31: According to Bond strategy | P31: -1 | Q31: 1 | R31: =M31*Q31 -> -14318.22 | S31: =ABS(R31) -> 14318.22 | T31: =S31/1000000 -> 0.01431822 | Y31: Adding ultra-long French OAT for Eurozone duration and convexity. Positioned for ECB easing and growth slowdown. Offers yield pickup versus Bunds while maintaining core sovereign risk profile. Complements German and US long-duration exposure. | AI31: Bond strategy
A32: 31 | B32: Wanchun Cui | C32: 46062.917 | D32: Market | E32: NY | F32: Fixed Income | G32: ASML Holding - 2.250% - May 2032 | H32: Bond | J32: Buy | K32: 968.99 | L32: 18 | M32: -17532.81 | O32: According to Bond strategy | P32: -1 | Q32: 1 | R32: =M32*Q32 -> -17532.81 | S32: =ABS(R32) -> 17532.81 | T32: =S32/1000000 -> 0.01753281 | Y32: Long ASML 2.25% May-2032 to gain high-quality tech IG exposure with moderate duration. Trade focuses on spread stability and rate sensitivity, supported by ASML’s monopoly-like industry position and strong balance sheet. | AI32: Bond strategy
A33: 32 | B33: Wanchun Cui | C33: 46062.917 | D33: Market | E33: NY | F33: Fixed Income | G33: Sanofi S.A - 1.875% - Mar 2038 | H33: Bond | J33: Buy | K33: 842.85 | L33: 8 | M33: -6799.92 | O33: According to Bond strategy | P33: -1 | Q33: 1 | R33: =M33*Q33 -> -6799.92 | S33: =ABS(R33) -> 6799.92 | T33: =S33/1000000 -> 0.00679992 | Y33: Non-financial IG anchor in Credit RV bucket. Defensive pharma cash flows with low beta. Used as spread benchmark versus bank credit to isolate financial sector-specific spread moves. | AI33: Bond strategy
A34: 33 | B34: Wanchun Cui | C34: 46062.917 | D34: Market | E34: NY | F34: Fixed Income | G34: TotalEnergies Capital Intl. - 1.535% - May 2039 | H34: Bond | J34: Buy | K34: 753 | L34: 6 | M34: -4535.41 | O34: According to Bond strategy | P34: -1 | Q34: 1 | R34: =M34*Q34 -> -4535.41 | S34: =ABS(R34) -> 4535.41 | T34: =S34/1000000 -> 0.00453541 | Y34: Non-financial IG energy credit added as macro-sensitive leg in Credit RV bucket. Provides diversification from tech and financials while linking portfolio to inflation and commodity dynamics. | AI34: Bond strategy
C35: 46063.012 | D35: CouponPayment | E35: Asia | F35: Fixed Income | G35: Kraft Heinz Foods - 6.500% - Feb 2040 | H35: Bond | J35: Buy | K35: 522.83542 | L35: 1 | M35: 522.84 | O35: According to Bond strategy | P35: -1 | Q35: 0.84269 | R35: =M35*Q35 -> 440.59204 | S35: =ABS(R35) -> 440.59204
A36: 34 | B36: Wanchun Cui | C36: 46063.125 | D36: Market | E36: Asia | F36: Fixed Income | G36: BUND 4.750% 04-Jul-2040 | H36: Bond | J36: Buy | K36: 1183.59 | L36: 12 | M36: -14256.18 | O36: According to Bond strategy | P36: -1 | Q36: 1 | R36: =M36*Q36 -> -14256.18 | S36: =ABS(R36) -> 14256.18 | T36: =S36/1000000 -> 0.01425618 | Y36: Non-financial IG energy credit added as macro-sensitive leg in Credit RV bucket. Provides diversification from tech and financials while linking portfolio to inflation and commodity dynamics.
A37: 35 | B37: Jade Sancho | C37: 46063.664 | D37: Limit | E37: NY | F37: Option | G37: Meta | H37: Call | I37: Long | J37: Buy | K37: 12.6 | L37: 50 | M37: -52892.73 | O37: Let's see where volatility brings us | P37: -1 | Q37: 0.83957 | R37: =M37*Q37 -> -44407.149 | S37: =ABS(R37) -> 44407.149 | T37: =S37/1000000 -> 0.044407149 | Y37: I used a call option on Meta to express a short-term bullish view following a market correction, benefiting from a potential rebound while keeping downside risk limited to the option premium
A38: 36 | B38: Jade Sancho | C38: 46063.719 | D38: Limit | E38: NY | F38: Option | G38: Microsoft | H38: Call | I38: Long | J38: Buy | K38: 6.05 | L38: 50 | M38: -25396.91 | O38: Let's see where volatility brings us | P38: -1 | Q38: 0.83957 | R38: =M38*Q38 -> -21322.484 | S38: =ABS(R38) -> 21322.484 | T38: =S38/1000000 -> 0.021322484 | Y38: Expect Microsoft to go up again as it is only rising since 5 february after crash
A39: 37 | B39: Wang Jialei | C39: 46063.742 | D39: Market | E39: NY | F39: Equities | G39: Netflix Inc. | H39: Equity | J39: Buy | K39: 83.42 | L39: 400 | M39: -28014.68 | O39: Looking for a 10% profit | P39: -1 | Q39: 0.83957 | R39: =M39*Q39 -> -23520.285 | S39: =ABS(R39) -> 23520.285 | T39: =S39/1000000 -> 0.023520285 | U39: =M39/1000000 -> -0.02801468 | V39: Safe haven | W39: Netflix is showing a downward tendency, wait for its future comback | X39: Its acqurition of Warner Bros | Y39: Its plan of acquiring WB show big potential of profitability | Z39: middle term | AA39: Confident | AI39: Long-only | AJ39: 5m
C40: 46069.015 | D40: CouponPayment | E40: Asia | F40: Fixed Income | G40: BUND 1.250% 15-Nov-2048 | H40: Bond | J40: Buy | K40: 137.5 | L40: 1 | M40: 137.5 | O40: According to Bond strategy | P40: -1 | Q40: 1 | R40: =M40*Q40 -> 137.5 | S40: =ABS(R40) -> 137.5 | T40: =S40/1000000 -> 0.0001375
...

Sheet Dashboard
A1: Full trade cycle | B1: Date | C1: Instrument | D1: Asset class | E1: Trader | F1: Net P&L | G1: Net P&L $ | H1: Portfolio wallet currently | I1: Portfolio $ | J1: 1000000 | K1: 1151240
A2: 1 | B2: 46044 | C2: EUR/USD | D2: FX | E2: Yannis Khalfi | F2: -1 | G2: 0
A3: 2 | B3: 46056 | C3: NVDA | D3: Call | E3: Jade Sancho | F3: -23876.22 | G3: -23876.22 | H3: =J1+F3 -> 976123.78 | I3: =J1+G3 -> 976123.78 | J3: Include Longest trade, shortest trade in python
A4: 3 | B4: 46056 | C4: NVDA | D4: Put | E4: Jade Sancho | F4: 25922.51 | G4: 25922.51 | H4: =H3+F4 -> 1002046.3 | I4: =I3+G4 -> 1002046.3 | J4: Include trades on NY / ASIA / LONDON on python
A5: 4 | B5: 46058 | C5: BTC | D5: Crypto | E5: Yannis Khalfi | F5: -3027.66 | G5: -3027.66 | H5: =H4+F5 -> 999018.63 | I5: =I4+G5 -> 999018.63 | J5: Include fees in python yannis
A6: 5 | B6: 46062 | C6: Microsoft | D6: Call | E6: Jade Sancho | F6: 46895.85 | G6: 46895.85 | H6: =H5+F6 -> 1045914.5 | I6: =I5+G6 -> 1045914.5 | J6: CETTE COLONNE PEUT FAIRE CRASH SI JE LA SUPPRIME DONC RECTIFIER CODE SUR EXPECTIF AXIS HAS 10 ELEMENTS, NEW VALUES HAVE 11 ELEMENTS
A7: 8 | B7: =Trading_Journal!C43 -> 46072.01 | C7: Microsoft | D7: Call | E7: Jade Sancho | F7: -25396.9 | G7: -25396.9 | H7: =H6+F7 -> 1020517.6 | I7: =I6+G7 -> 1020517.6
A8: 9 | B8: =Trading_Journal!C44 -> 46072.01 | C8: Meta | D8: Call | E8: Jade Sancho | F8: -52892.72 | G8: -52892.72 | H8: =H7+F8 -> 967624.86 | I8: =I7+G8 -> 967624.86
A9: 10 | B9: =Trading_Journal!C45 -> 46073.806 | C9: Microsoft | D9: Put | E9: Jade Sancho | F9: -12949.48 | G9: -12949.48 | H9: =H8+F9 -> 954675.38 | I9: =I8+G9 -> 954675.38
A10: 11 | B10: =Trading_Journal!C46 -> 46073.806 | C10: Meta | D10: Put | E10: Jade Sancho | F10: -36328.34 | G10: -36328.34 | H10: =H9+F10 -> 918347.04 | I10: =I9+G10 -> 918347.04
A11: 12 | B11: 46080 | C11: Netflix | D11: Equity | E11: Wang Jialei | F11: 3630.02 | G11: 3630.02 | H11: =H10+F11 -> 921977.06 | I11: =I10+G11 -> 921977.06
A12: 19 | B12: 46086 | C12: SPDR GOLD TRUST ETF | D12: Call | E12: Yannis Khalfi | F12: =3429.13+7537.53 -> 10966.66 | G12: =3429.13+7537.53 -> 10966.66 | H12: =H11+F12 -> 932943.72 | I12: =I11+G12 -> 932943.72
A13: 20 | B13: 46087 | C13: Marvell Technol. | D13: Equity | E13: Yannis Khalfi | F13: 360.38 | G13: 360.38 | H13: =H12+F13 -> 933304.1 | I13: =I12+G13 -> 933304.1
A14: 21 | B14: 46087 | C14: Okta Inc - Ordi... | D14: Equity | E14: Yannis Khalfi | F14: 495.54 | G14: 495.54 | H14: =H13+F14 -> 933799.64 | I14: =I13+G14 -> 933799.64
A15: 22 | B15: 46088.011 | C15: SPDR GOLD TRUST ETF | D15: Call | E15: Yannis Khalfi | F15: =-9467.21 - 20547.66 -> -30014.87 | G15: =-9467.21 - 20547.66 -> -30014.87 | H15: =H14+F15 -> 903784.77 | I15: =I14+G15 -> 903784.77
A16: 23 | B16: 46092.747 | C16: SPDR GOLD TRUST ETF | D16: Call | E16: Yannis Khalfi | F16: 16127.88 | G16: 16127.88 | H16: =H15+F16 -> 919912.65 | I16: =I15+G16 -> 919912.65
A17: 24 | B17: 46094.769 | C17: JD.com Inc - | D17: Equity | E17: Yannis Khalfi | F17: 957.18 | G17: 957.18 | H17: =H16+F17 -> 920869.83 | I17: =I16+G17 -> 920869.83
A18: 25 | B18: 46094.769 | C18: Micron Technolo... | D18: Equity | E18: Yannis Khalfi | F18: 199.18 | G18: 199.18 | H18: =H17+F18 -> 921069.01 | I18: =I17+G18 -> 921069.01
A19: 26 | B19: 46094.969 | C19: SPDR GOLD TRUST ETF | D19: Call | E19: Yannis Khalfi | F19: -32158.79 | G19: -32158.79 | H19: =H18+F19 -> 888910.22 | I19: =I18+G19 -> 888910.22
A20: 27 | B20: 46097.685 | C20: Intel Corp. | D20: Equity | E20: Yannis Khalfi | F20: 524.31 | G20: 524.31 | H20: =H19+F20 -> 889434.53 | I20: =I19+G20 -> 889434.53
A21: 28 | B21: 46098.724 | C21: FET | D21: Crypto | E21: Wanchun Cui | F21: 2922.27 | G21: 2922.27 | H21: =H20+F21 -> 892356.8 | I21: =I20+G21 -> 892356.8
A22: 29 | B22: 46099.001 | C22: RNDR | D22: Crypto | E22: Wanchun Cui | F22: =1370.82 - 32.57 -> 1338.25 | G22: =1370.82 - 32.57 -> 1338.25 | H22: =H21+F22 -> 893695.05 | I22: =I21+G22 -> 893695.05
A23: 30 | B23: 46099.001 | C23: GBP/USD | D23: FX | E23: Wang Jialei | F23: =-260.17 -> -260.17 | G23: =-260.17 -> -260.17 | H23: =H22+F23 -> 893434.88 | I23: =I22+G23 -> 893434.88
A24: 31 | B24: 46099.001 | C24: EUR/USD | D24: FX | E24: Wang Jialei | F24: -564.91 | G24: -564.91 | H24: =H23+F24 -> 892869.97 | I24: =I23+G24 -> 892869.97
A25: 32 | B25: 46099.604 | C25: GOLD | D25: Commodity | E25: Yannis Khalfi | F25: -3029.63 | G25: -3029.63 | H25: =H24+F25 -> 889840.34 | I25: =I24+G25 -> 889840.34
A26: 33 | B26: 46099.604 | C26: SILVER | D26: Commodity | E26: Yannis Khalfi | F26: -10538.04 | G26: -10538.04 | H26: =H25+F26 -> 879302.3 | I26: =I25+G26 -> 879302.3
A27: 34 | B27: 46099.657 | C27: BTC | D27: Crypto | E27: Wanchun Cui | F27: -323.25 | G27: -323.25 | H27: =H26+F27 -> 878979.05 | I27: =I26+G27 -> 878979.05
A28: 35 | B28: 46099.657 | C28: LINK | D28: Crypto | E28: Wanchun Cui | F28: =67.57 - 575.61 -> -508.04 | G28: =67.57 - 575.61 -> -508.04 | H28: =H27+F28 -> 878471.01 | I28: =I27+G28 -> 878471.01
A29: 36 | B29: 46099.657 | C29: UNI | D29: Crypto | E29: Wanchun Cui | F29: =-211.25-640.52 -> -851.77 | G29: =-211.25-640.52 -> -851.77 | H29: =H28+F29 -> 877619.24 | I29: =I28+G29 -> 877619.24
A30: 37 | B30: 46099.657 | C30: SOL | D30: Crypto | E30: Wanchun Cui | F30: =179.69 - 589.15+1508.22 -> 1098.76 | G30: =179.69 - 589.15+1508.22 -> 1098.76 | H30: =H29+F30 -> 878718 | I30: =I29+G30 -> 878718
A31: 38 | B31: 46099.657 | C31: OP | D31: Crypto | E31: Wanchun Cui | F31: =-373.3 -> -373.3 | G31: 0 | H31: =H30+F31 -> 878344.7 | I31: =I30+G31 -> 878718
A32: 39 | B32: 46099.657 | C32: BTP 3.100% 03-Jan-2040 | D32: Bond | E32: Wanchun Cui | F32: -309.85 | G32: -309.85 | H32: =H31+F32 -> 878034.85 | I32: =I31+G32 -> 878408.15
A33: 40 | B33: 46099.657 | C33: JPMORGAN CHASE & CO - 5.5% - Oct 2040 | D33: Bond | E33: Wanchun Cui | F33: 56.55 | G33: 56.55 | H33: =H32+F33 -> 878091.4 | I33: =I32+G33 -> 878464.7
A34: 41 | B34: 46099.657 | C34: JPMORGAN CHASE & CO - 6.4% - May 2038 | D34: Bond | E34: Wanchun Cui | F34: 19.74 | G34: 19.74 | H34: =H33+F34 -> 878111.14 | I34: =I33+G34 -> 878484.44
A35: 42 | B35: 46099.657 | C35: Philip Morris - 6.375% - May 2038 | D35: Bond | E35: Wanchun Cui | F35: 121.46 | G35: 121.46 | H35: =H34+F35 -> 878232.6 | I35: =I34+G35 -> 878605.9
A36: 43 | B36: 46099.657 | C36: Boeing | D36: Bond | E36: Wanchun Cui | F36: 590.31 | G36: 590.31 | H36: =H35+F36 -> 878822.91 | I36: =I35+G36 -> 879196.21
A37: 44 | B37: 46099.657 | C37: Ford Motor Co. - 7.500% - Aug 2026 | D37: Bond | E37: Wanchun Cui | F37: 313 | G37: 313 | H37: =H36+F37 -> 879135.91 | I37: =I36+G37 -> 879509.21
A38: 45 | B38: 46099.657 | C38: Apple Inc - 1.700% - Aug 2031 | D38: Bond | E38: Wanchun Cui | F38: 270.69 | G38: 270.69 | H38: =H37+F38 -> 879406.6 | I38: =I37+G38 -> 879779.9
A39: 46 | B39: 46099.657 | C39: United States Steel Corp - 6.875% - Mar 2029 | D39: Bond | E39: Wanchun Cui | F39: 162.71 | G39: 162.71 | H39: =H38+F39 -> 879569.31 | I39: =I38+G39 -> 879942.61
A40: 47 | B40: 46099.657 | C40: Kraft Heinz Foods - 6.500% - Feb 2040 | D40: Bond | E40: Wanchun Cui | F40: 225.91 | G40: 225.91 | H40: =H39+F40 -> 879795.22 | I40: =I39+G40 -> 880168.52
...

Sheet Bonds
A1: Issuer | B1: Country | C1: Bond Type | D1: Industry | E1: Coupon (%) | F1: Maturity | G1: Tenor | H1: Yield Style | I1: Notes | K1: Issuer | L1: (Tous)
A2: 21st Century Fox Amer Inc | B2: US | C2: Corporate | D2: Media | E2: 6.65 | F2: 13820 | G2: Long | H2: High | I2: Media company | K2: Bond Type | L2: (Tous) | M2: YOU ARE AMAZING, Good luck ! by Yannis
A3: 21st Century Fox Amer Inc | B3: US | C3: Corporate | D3: Media | E3: 6.4 | F3: 13119 | G3: Long | H3: High | I3: Media company
A4: 7-Eleven Inc | B4: US | C4: Corporate | D4: Retail | E4: 1.3 | F4: 46081 | G4: Short | H4: Low | I4: Convenience retail | K4: Country
A5: 7-Eleven Inc | B5: US | C5: Corporate | D5: Retail | E5: 2.5 | F5: 15008 | G5: Long | H5: Low | I5: Convenience retail | K5: France
A6: Apple Inc | B6: US | C6: Corporate | D6: Technology | E6: 3.25 | F6: 46079 | G6: Short | H6: Medium | I6: Large tech | K6: Germany
A7: Apple Inc | B7: US | C7: Corporate | D7: Technology | E7: 3.25 | F7: 46263 | G7: Medium | H7: Medium | I7: Large tech | K7: Italy
A8: Apple Inc | B8: US | C8: Corporate | D8: Technology | E8: 1.7 | F8: 46265 | G8: Medium | H8: Low | I8: Large tech | K8: Netherlands
A9: Abbott Labs | B9: US | C9: Corporate | D9: Healthcare | E9: 6 | F9: 14336 | G9: Long | H9: High | I9: Healthcare | K9: UK
A10: Abbott Labs | B10: US | C10: Corporate | D10: Healthcare | E10: 4.75 | F10: 15797 | G10: Long | H10: Medium | I10: Healthcare | K10: US
A11: AbbVie Inc | B11: US | C11: Corporate | D11: Healthcare | E11: 4.4 | F11: 15646 | G11: Long | H11: Medium | I11: Pharma | K11: Total général
A12: Adobe Inc | B12: US | C12: Corporate | D12: Technology | E12: 2.3 | F12: 10990 | G12: Medium | H12: Low | I12: Software
A13: Advanced Micro Devices Inc | B13: US | C13: Corporate | D13: Technology | E13: 3.924 | F13: 11841 | G13: Medium | H13: Medium | I13: Semiconductors
A14: Advanced Micro Devices Inc | B14: US | C14: Corporate | D14: Technology | E14: 4.393 | F14: 19146 | G14: Very Long | H14: Medium | I14: Semiconductors
A15: Alphabet Inc | B15: US | C15: Corporate | D15: Technology | E15: 1.1 | F15: 46264 | G15: Medium | H15: Low | I15: Internet services
A16: Alphabet Inc | B16: US | C16: Corporate | D16: Technology | E16: 1.9 | F16: 14824 | G16: Long | H16: Low | I16: Internet services
A17: Allstate Corp | B17: US | C17: Corporate | D17: Insurance | E17: 7.526 | F17: 19572 | G17: Very Long | H17: High | I17: Insurance
A18: Altria Group Inc | B18: US | C18: Corporate | D18: Consumer Staples | E18: 10.2 | F18: 14277 | G18: Long | H18: High | I18: Tobacco
A19: Altria Group Inc | B19: US | C19: Corporate | D19: Consumer Staples | E19: 9.95 | F19: 14185 | G19: Long | H19: High | I19: Tobacco
A20: Altria Group Inc | B20: US | C20: Corporate | D20: Consumer Staples | E20: 5.375 | F20: 16072 | G20: Long | H20: Medium | I20: Tobacco
A21: Alcan Inc | B21: US | C21: Corporate | D21: Materials | E21: 7.25 | F21: 46354 | G21: Short | H21: High | I21: Aluminum
A22: Avangrid Inc | B22: US | C22: Corporate | D22: Utilities | E22: 3.8 | F22: 46202 | G22: Medium | H22: Low | I22: Utilities
A23: Aflac Inc | B23: US | C23: Corporate | D23: Insurance | E23: 6.9 | F23: 14580 | G23: Long | H23: High | I23: Insurance
... A105: US Treasury | B105: US | C105: Government | D105: Government | E105: 4.25 | F105: 14380 | G105: Long | H105: Medium | I105: Long duration
A106: US Treasury | B106: US | C106: Government | D106: Government
A107: 3i Group | B107: UK | C107: Corporate | D107: Financials | E107: 5.75 | F107: 12024 | G107: Medium | H107: Medium | I107: Private equity group
A108: 3i Group | B108: UK | C108: Corporate | D108: Financials | E108: 3.75 | F108: 14763 | G108: Long | H108: Low | I108: Private equity group
A109: Aviva PLC | B109: UK | C109: Corporate | D109: Insurance | E109: 6.125 | F109: 13455 | G109: Long | H109: Medium | I109: Insurance
A110: Aviva PLC | B110: UK | C110: Corporate | D110: Insurance | E110: 4.375 | F110: 18142 | G110: Very Long | H110: Medium | I110: Insurance
A111: BP PLC | B111: UK | C111: Corporate | D111: Energy | E111: 5.773 | F111: 14001 | G111: Long | H111: Medium | I111: Oil & gas
A112: British Telecom PLC | B112: UK | C112: Corporate | D112: Communications | E112: 5.75 | F112: 46384 | G112: Short | H112: Medium | I112: Telecom
A113: British Telecom PLC | B113: UK | C113: Corporate | D113: Communications | E113: 3.125 | F113: 11628 | G113: Medium | H113: Low | I113: Telecom
A114: British Telecom PLC | B114: UK | C114: Corporate | D114: Communications | E114: 6.375 | F114: 13667 | G114: Long | H114: Medium | I114: Telecom
A115: Burberry Group | B115: UK | C115: Corporate | D115: Consumer Discretionary | E115: 5.75 | F115: 46203 | G115: Medium | H115: Medium | I115: Luxury retail
A116: HSBC Holdings PLC | B116: UK | C116: Corporate | D116: Financials | E116: 5.375 | F116: 46356 | G116: Medium | H116: Medium | I116: Banking
A117: HSBC Holdings PLC | B117: UK | C117: Corporate | D117: Financials | E117: 6 | F117: 14671 | G117: Long | H117: Medium | I117: Banking
A118: Lloyds Banking Group | B118: UK | C118: Corporate | D118: Financials | E118: 2 | F118: 46140 | G118: Short | H118: Low | I118: Banking
... A205: Italian Treasury (BTP) | B205: Italy | C205: Government | D205: Government | E205: 4.75 | F205: 16080 | G205: Long | H205: Medium | I205: BTP

Sheet Bonds Strategy
A1: Investment Grade Allocation (75% = USD 1,500,000) | C1: 18 bonds | D1: 300000
B2: To systematically learn interest rate dynamics, duration effects, yield curve behavior, and sector credit spreads, while maintaining portfolio stability. | D2: YOU ARE AMAZING, Good luck ! by Yannis
B3: IG-1 | Government Bonds – Duration Lab
C4: 30% of total bonds = USD 600,000 Government bonds isolate interest rate risk from credit risk Long and medium duration bonds allow us to observe price sensitivity to rate movements 30% provides meaningful duration exposure without dominating the portfolio
B5: Bond | C5: Country | D5: Maturity | E5: Weight | F5: Amount | H5: Why this bond & this weight
B6: US Treasury 15-May-2040 | C6: US | D6: 2040 | E6: 0.1 | F6: 200000 | G6: =$D$1*E6 -> 30000 | H6: Very long duration; maximizes sensitivity to rate changes, ideal for learning convexity
B7: US Treasury 15-Feb-2031 | C7: US | D7: 2031 | E7: 0.08 | F7: 160000 | G7: =$D$1*E7 -> 24000 | H7: Medium duration benchmark; serves as reference point on the US curve
B8: German Bund 04-Jul-2040 | C8: Germany | D8: 2040 | E8: 0.06 | F8: 120000 | G8: =$D$1*E8 -> 18000 | H8: Core EUR risk-free asset; allows comparison between USD and EUR rate dynamics
B9: French OAT 25-May-2043 | C9: France | D9: 2043 | E9: 0.06 | F9: 120000 | G9: =$D$1*E9 -> 18000 | H9: Slightly higher sovereign spread vs Bund; used to study sovereign risk premium
B11: IG-2 | Investment-Grade Corporates – Sector Comparison
C12: 30% of total bonds = USD 600,000 Same credit quality, different industries Allows analysis of sector-specific credit spreads Balanced exposure across defensive and cyclical sectors
B13: Bond | C13: Sector | D13: Maturity | E13: Weight | F13: Amount | H13: Why this bond & this weight
B14: Apple Inc 3.25% Feb-2026 | C14: Technology | D14: 2026 | E14: 0.06 | F14: 120000 | H14: Ultra-high-quality IG; acts as quasi risk-free corporate benchmark
B15: Microsoft Corp 5.20% Jun-2039 | C15: Technology | D15: 2039 | E15: 0.06 | F15: 120000 | H15: Long-term IG tech; combines duration risk with strong fundamentals
B16: Johnson & Johnson 4.95% May-2033 | C16: Healthcare | D16: 2033 | E16: 0.06 | F16: 120000 | H16: Defensive cash flows; low cyclicality
B17: JPMorgan Chase 5.50% Oct-2040 | C17: Financials | D17: 2040 | E17: 0.06 | F17: 120000 | H17: Financial sector exposure; sensitive to economic and rate cycles
B18: Enel Finance Intl 3.875% Mar-2029 | C18: Utilities | D18: 2029 | E18: 0.06 | F18: 120000 | H18: Stable regulated cash flows; lower spread volatility
B20: IG-3 | IG Curve & Geography
C21: 15% of total bonds = USD 300,000 Compare EUR vs USD investment-grade credit Same tenor, different countries and sectors Smaller allocation as this is a comparative, not core, experiment
B22: Bond | C22: Country | D22: Maturity | E22: Weight | F22: Amount | H22: Why this bond & this weight
B23: AXA S.A. 3.25% May-2029 | C23: France | D23: 2029 | E23: 0.05 | F23: 100000 | H23: European insurance IG; financial sector in EUR
B24: Deutsche Telekom 1.75% Mar-2031 | C24: Germany | D24: 2031 | E24: 0.05 | F24: 100000 | H24: Core European telecom; low-risk EUR corporate
B25: Nestlé / Danone equivalent | C25: Europe | D25: 2029 | E25: 0.05 | F25: 100000 | H25: Defensive consumer exposure; stable margins
A27: High Yield Allocation (25% = USD 500,000)
B28: To observe how credit risk is priced, repriced, and amplified, while strictly limiting downside risk.
B29: HY-1 | Fallen Angels / Near-IG
C30: 40% of HY = USD 200,000 Former IG issuers provide a clean view of downgrade risk Often show spread compression if fundamentals stabilize
B31: Bond | C31: Sector | D31: Maturity | E31: Weight | F31: Amount | H31: Why this bond & this weight
B32: Ford Motor 7.5% Aug-2026 | C32: Industrials | D32: 2026 | E32: 0.1 | F32: 200000 | H32: Classic fallen angel; short maturity limits risk while allowing spread recovery analysis
B34: HY-2 | Cyclical High Yield
C35: 35% of HY = USD 175,000 Credit risk strongly linked to economic cycles Allows observation of macro → cash flow → credit spread transmission
B36: Bond | C36: Sector | D36: Maturity | E36: Weight | F36: Amount | H36: Why this bond & this weight
B37: ENI S.p.A. 4.25% May-2033 | C37: Energy | D37: 2033 | E37: 0.09 | F37: 180000 | H37: Commodity-linked cash flows; credit sensitive to oil prices
B38: Boeing 6.875% Oct-2043 | C38: Industrials | D38: 2043 | E38: 0.08 | F38: 160000 | H38: High leverage and long maturity; strong credit cyclicality
B40: HY-3 | Stable Cash Flow High Yield
C41: 5% of HY = USD 125,000 High leverage but predictable cash flows Shows why markets demand high spreads even for stable businesses
B42: Bond | C42: Sector | D42: Maturity | E42: Weight | F42: Amount | H42: Why this bond & this weight
B43: Altria Group 9.95% Nov-2038 | C43: Consumer Staples | D43: 2038 | E43: 0.06 | F43: 120000 | H43: Very high coupon; stable tobacco cash flows
B44: Philip Morris 6.375% May-2038 | C44: Consumer Staples | D44: 2038 | E44: 0.06 | F44: 120000 | H44: Defensive HY; strong pricing power
A50: Bonds Strategy Version 2
...
